<?xml version="1.0" encoding="utf-8"?>
<!-- This URDF was automatically created by SolidWorks to URDF Exporter! Originally created by Stephen Brawner (brawner@gmail.com) 
     Commit Version: 1.6.0-4-g7f85cfe  Build Version: 1.6.7995.38578
     For more information, please see http://wiki.ros.org/sw_urdf_exporter -->
     
<robot xmlns:xacro="http://www.ros.org/wiki/xacro" name="hydra_description">
  
  <xacro:arg name="is_ignition" default="true"/>
	
  <xacro:include filename="$(find hydra_description)/urdf/hydra_gazebo.xacro" />
  <xacro:include filename="$(find hydra_description)/urdf/hydra_ros2_control.xacro" />

  <!-- Useful XACRO Variables (Properties) -->
  <xacro:property name="PI" value="3.14159265359" />
  <xacro:property name="effort" value="30.0" />
  <xacro:property name="velocity" value="10.0" />
 
  <link name="world"/>
  <link
    name="base_link">
    <inertial>
      <origin
         xyz="-0.13048 -0.58853 0.037721"
         rpy="-1.5708 0 -1.5708" />
      <mass
        value="0.123964510694144" />
      <inertia
        ixx="0.000182981610346539"
        ixy="-6.18471848320969E-07"
        ixz="-3.11137707654155E-08"
        iyy="0.000322626757057039"
        iyz="1.00978335752959E-08"
        izz="0.000186833490505533" />
    </inertial>
    <visual>
      <origin
        xyz="0.13 0.59 0"
        rpy="0 0 0" />
      <geometry>
        <mesh
          filename="package://hydra_description/meshes/base_link.STL" />
      </geometry>
      <material
        name="">
        <color
          rgba="0.501960784313725 0.501960784313725 0.501960784313725 1" />
      </material>
    </visual>
    <collision>
      <origin
        xyz="0 0 0"
        rpy="0 0 0" />
      <geometry>
        <mesh
          filename="package://hydra_description/meshes/base_link.STL" />
      </geometry>
    </collision>
  </link>
  <link
    name="rotatable_base_link">
    <inertial>
      <origin
        xyz="-0.00741407552981677 -0.035058624413814 0.0043311715549548"
        rpy="0 0 0" />
      <mass
        value="0.159781950527547" />
      <inertia
        ixx="0.000112056164773301"
        ixy="-2.76211773084231E-08"
        ixz="-9.34444737900659E-13"
        iyy="0.000100380036750858"
        iyz="-1.92885377952631E-12"
        izz="7.77943283200645E-05" />
    </inertial>
    <visual>
      <origin
        xyz="0 0 0"
        rpy="0 0 0" />
      <geometry>
        <mesh
          filename="package://hydra_description/meshes/rotatable_base_link.STL" />
      </geometry>
      <material
        name="">
        <color
          rgba="0.792156862745098 0.819607843137255 0.933333333333333 1" />
      </material>
    </visual>
    <collision>
      <origin
        xyz="0 0 0"
        rpy="0 0 0" />
      <geometry>
        <mesh
          filename="package://hydra_description/meshes/rotatable_base_link.STL" />
      </geometry>
    </collision>
  </link>
  
  <joint name="virtual_joint" type="fixed">
     <parent link="world"/>
     <child link="base_link"/>
     <origin xyz="0 0 0" rpy="0 0 0"/>
  </joint> 
  
  <joint
    name="joint_0"
    type="revolute">
    <origin
      xyz="0 0 0.037721"
      rpy="-1.5708 0 -1.5708" />
    <parent
      link="base_link" />
    <child
      link="rotatable_base_link" />
    <axis
      xyz="0 1 0" />
    <limit
      lower="-1.57"
      upper="1.57"
      effort="${effort}"
      velocity="${velocity}" />
  </joint>

  <link
    name="lower_link">
    <inertial>
      <origin
        xyz="-0.0165413072201235 -9.09566380546956E-10 -0.0972204695509715"
        rpy="0 0 0" />
      <mass
        value="0.479586072695612" />
      <inertia
        ixx="0.00185931368222127"
        ixy="6.53064368270066E-13"
        ixz="2.83637417264087E-07"
        iyy="0.00172384115503623"
        iyz="-2.51580285500852E-12"
        izz="0.000167226383363547" />
    </inertial>
    <visual>
      <origin
        xyz="0 0 0"
        rpy="0 0 0" />
      <geometry>
        <mesh
          filename="package://hydra_description/meshes/lower_link.STL" />
      </geometry>
      <material
        name="">
        <color
          rgba="0.501960784313725 0.501960784313725 0.501960784313725 1" />
      </material>
    </visual>
    <collision>
      <origin
        xyz="0 0 0"
        rpy="0 0 0" />
      <geometry>
        <mesh
          filename="package://hydra_description/meshes/lower_link.STL" />
      </geometry>
    </collision>
  </link>

  <joint
    name="joint_1"
    type="revolute">
    <origin
      xyz="-0.02 -0.05 0"
      rpy="1.8356 0 3.1416" />
    <parent
      link="rotatable_base_link" />
    <child
      link="lower_link" />
    <axis
      xyz="1 0 0" />
    <limit
      lower="-1.57"
      upper="1.57"
      effort="${effort}"
      velocity="${velocity}" />
  </joint>
  <link
    name="middle_link">
    <inertial>
      <origin
        xyz="-0.00557828049195652 -0.00039014946610158 -0.0591420033692123"
        rpy="0 0 0" />
      <mass
        value="0.230863992660165" />
      <inertia
        ixx="0.000558080760363236"
        ixy="-1.40393722851452E-08"
        ixz="-7.40172951045167E-09"
        iyy="0.000522367476537509"
        iyz="-8.27188829974406E-06"
        izz="7.00404271316846E-05" />
    </inertial>
    <visual>
      <origin
        xyz="0 0 0"
        rpy="0 0 0" />
      <geometry>
        <mesh
          filename="package://hydra_description/meshes/middle_link.STL" />
      </geometry>
      <material
        name="">
        <color
          rgba="0.501960784313725 0.501960784313725 0.501960784313725 1" />
      </material>
    </visual>
    <collision>
      <origin
        xyz="0 0 0"
        rpy="0 0 0" />
      <geometry>
        <mesh
          filename="package://hydra_description/meshes/middle_link.STL" />
      </geometry>
    </collision>
  </link>
  <joint
    name="joint_2"
    type="revolute">
    <origin
      xyz="-0.02 0.0063552 -0.18258"
      rpy="-0.5902 0 3.1416" />
    <parent
      link="lower_link" />
    <child
      link="middle_link" />
    <axis
      xyz="1 0 0" />
    <limit
      lower="-1.57"
      upper="1.57"
      effort="${effort}"
      velocity="${velocity}" />
  </joint>
  <link
    name="upper_link">
    <inertial>
      <origin
        xyz="0.00596138176290451 0.0226145656395636 0.0272411601684721"
        rpy="0 0 0" />
      <mass
        value="0.244614595031632" />
      <inertia
        ixx="0.000231280778096435"
        ixy="2.82908146522814E-08"
        ixz="3.63896956475846E-08"
        iyy="0.000139819511532059"
        iyz="-4.75373352863529E-05"
        izz="0.000112356531354506" />
    </inertial>
    <visual>
      <origin
        xyz="0 0 0"
        rpy="0 0 0" />
      <geometry>
        <mesh
          filename="package://hydra_description/meshes/upper_link.STL" />
      </geometry>
      <material
        name="">
        <color
          rgba="0.501960784313725 0.501960784313725 0.501960784313725 1" />
      </material>
    </visual>
    <collision>
      <origin
        xyz="0 0 0"
        rpy="0 0 0" />
      <geometry>
        <mesh
          filename="package://hydra_description/meshes/upper_link.STL" />
      </geometry>
    </collision>
  </link>
  <joint
    name="joint_3"
    type="revolute">
    <origin
      xyz="0 0.00025 -0.1175"
      rpy="-0.53258 0 3.1416" />
    <parent
      link="middle_link" />
    <child
      link="upper_link" />
    <axis
      xyz="1 0 0" />
    <limit
      lower="-1.57"
      upper="1.57"
      effort="${effort}"
      velocity="${velocity}" />
  </joint>
  <link
    name="wrist_link">
    <inertial>
      <origin
        xyz="0.0166698054885156 0.00269653329723316 -0.00102084766317079"
        rpy="0 0 0" />
      <mass
        value="0.0550361919538315" />
      <inertia
        ixx="1.11139123675182E-05"
        ixy="-9.68095293077911E-07"
        ixz="2.01268385557504E-07"
        iyy="1.83444534884964E-05"
        iyz="-1.03422347385584E-09"
        izz="1.01026654376445E-05" />
    </inertial>
    <visual>
      <origin
        xyz="0 0 0"
        rpy="0 0 0" />
      <geometry>
        <mesh
          filename="package://hydra_description/meshes/wrist_link.STL" />
      </geometry>
      <material
        name="">
        <color
          rgba="0.752941176470588 0.752941176470588 0.752941176470588 1" />
      </material>
    </visual>
    <collision>
      <origin
        xyz="0 0 0"
        rpy="0 0 0" />
      <geometry>
        <mesh
          filename="package://hydra_description/meshes/wrist_link.STL" />
      </geometry>
    </collision>
  </link>
  <joint
    name="joint_4"
    type="revolute">
    <origin
      xyz="0.0031 0.074138 0.063409"
      rpy="1.5708 -0.92593 1.5708" />
    <parent
      link="upper_link" />
    <child
      link="wrist_link" />
    <axis
      xyz="1 0 0" />
    <limit
      lower="-1.57"
      upper="1.57"
      effort="${effort}"
      velocity="${velocity}" />
  </joint>
  <link
    name="left_gripper_link">
    <inertial>
      <origin
        xyz="-0.0318348627246832 -0.0360451861289555 -0.0142262545937367"
        rpy="0 0 0" />
      <mass
        value="0.0163282646741853" />
      <inertia
        ixx="1.31332907957494E-06"
        ixy="-9.97170683994659E-07"
        ixz="1.40363646782336E-09"
        iyy="3.92463298783847E-06"
        iyz="3.79933520571904E-09"
        izz="4.6874989244787E-06" />
    </inertial>
    <visual>
      <origin
        xyz="0 0 0"
        rpy="0 0 0" />
      <geometry>
        <mesh
          filename="package://hydra_description/meshes/left_gripper_link.STL" />
      </geometry>
      <material
        name="">
        <color
          rgba="0.792156862745098 0.819607843137255 0.933333333333333 1" />
      </material>
    </visual>
    <collision>
      <origin
        xyz="0 0 0"
        rpy="0 0 0" />
      <geometry>
        <mesh
          filename="package://hydra_description/meshes/left_gripper_link.STL" />
      </geometry>
    </collision>
  </link>
  <joint
    name="joint_5"
    type="revolute">
    <origin
      xyz="0.036791 0 0"
      rpy="-1.5708 -0.1576 3.1416" />
    <parent
      link="wrist_link" />
    <child
      link="left_gripper_link" />
    <axis
      xyz="0 0 1" />
    <limit
      lower="-1.57"
      upper="1.57"
      effort="${effort}"
      velocity="${velocity}" />
  </joint>
  <link
    name="right_gripper_link">
    <inertial>
      <origin
        xyz="0.0446126006052641 -0.0174013842095694 0.0142380105116466"
        rpy="0 0 0" />
      <mass
        value="0.0163529802252157" />
      <inertia
        ixx="2.95937889565488E-06"
        ixy="1.60740986793684E-06"
        ixz="4.04415279259065E-09"
        iyy="2.27972601056359E-06"
        iyz="1.55881458006983E-12"
        izz="4.68843871994854E-06" />
    </inertial>
    <visual>
      <origin
        xyz="0 0 0"
        rpy="0 0 0" />
      <geometry>
        <mesh
          filename="package://hydra_description/meshes/right_gripper_link.STL" />
      </geometry>
      <material
        name="">
        <color
          rgba="0.792156862745098 0.819607843137255 0.933333333333333 1" />
      </material>
    </visual>
    <collision>
      <origin
        xyz="0 0 0"
        rpy="0 0 0" />
      <geometry>
        <mesh
          filename="package://hydra_description/meshes/right_gripper_link.STL" />
      </geometry>
    </collision>
  </link>
  <joint
    name="joint_6"
    type="revolute">
    <origin
      xyz="0.036791 0 0"
      rpy="-1.5708 1.058 0" />
    <parent
      link="wrist_link" />
    <child
      link="right_gripper_link" />
    <axis
      xyz="0 0 1" />
    <limit
      lower="-1.57"
      upper="1.57"
      effort="${effort}"
      velocity="${velocity}" />
    <mimic
      joint="joint_5"
      multiplier="1"
      offset="0" />
  </joint>
</robot>
